Workbook

Sheet Comparison Data
A1: Category | B1: Food First Product | C1: Food First Basis | D1: Food First Std Price (BBD) | E1: Supermarket A: Quantity/Basis | F1: Supermarket A Unit | G1: Supermarket A Shelf Price (BBD) | H1: Supermarket A Std Price (BBD) | I1: Supermarket B: Quantity/Basis | J1: Supermarket B Unit | K1: Supermarket B Shelf Price (BBD) | L1: Supermarket B Std Price (BBD) | M1: Food First vs Supermarket A % | N1: Food First vs Supermarket B % | O1: Supermarket A vs Supermarket B % | P1: Cheapest | Q1: Note
A2: Vegetables | B2: Broccoli | C2: kg | D2: 14 | E2: Kg | F2: BBD/kg | G2: 14.99 | H2: 14.99 | I2: Kg | J2: BBD/kg | K2: 15.99 | L2: 15.99 | M2: =D2/H2-1 -> -0.066044029 | N2: =D2/L2-1 -> -0.12445278 | O2: =H2/L2-1 -> -0.062539087 | P2: =IF(D2<=MIN(H2,L2),"Food First",IF(H2<=L2,"Supermarket A","Supermarket B")) -> Food First
A3: Vegetables | B3: Cauliflower | C3: kg | D3: 11.4 | E3: Kg | F3: BBD/kg | G3: 14.99 | H3: 14.99 | I3: Kg | J3: BBD/kg | K3: 17.99 | L3: 17.99 | M3: =D3/H3-1 -> -0.239493 | N3: =D3/L3-1 -> -0.36631462 | O3: =H3/L3-1 -> -0.16675931 | P3: =IF(D3<=MIN(H3,L3),"Food First",IF(H3<=L3,"Supermarket A","Supermarket B")) -> Food First
A4: Vegetables | B4: Romaine Lettuce | C4: unit | D4: 5 | E4: 1 head (0.3 kg) | F4: BBD/unit | G4: 7.99 | H4: 7.99 | I4: 1 head (0.2 kg) | J4: BBD/unit | K4: 5.79 | L4: 5.79 | M4: =D4/H4-1 -> -0.37421777 | N4: =D4/L4-1 -> -0.13644214 | O4: =H4/L4-1 -> 0.37996546 | P4: =IF(D4<=MIN(H4,L4),"Food First",IF(H4<=L4,"Supermarket A","Supermarket B")) -> Food First | Q4: Compared per head; recorded head weights differ.
A5: Vegetables | B5: Iceberg Lettuce | C5: unit | D5: 4.5 | E5: 1 head | F5: BBD/unit | G5: 5.99 | H5: 5.99 | I5: 1 head | J5: BBD/unit | K5: 6.99 | L5: 6.99 | M5: =D5/H5-1 -> -0.24874791 | N5: =D5/L5-1 -> -0.35622318 | O5: =H5/L5-1 -> -0.14306152 | P5: =IF(D5<=MIN(H5,L5),"Food First",IF(H5<=L5,"Supermarket A","Supermarket B")) -> Food First
A6: Vegetables | B6: Local Cabbage | C6: kg | D6: 3.5 | E6: Kg | F6: BBD/kg | G6: 6.59 | H6: 6.59 | I6: Kg | J6: BBD/kg | K6: 7.89 | L6: 7.89 | M6: =D6/H6-1 -> -0.46889226 | N6: =D6/L6-1 -> -0.55640051 | O6: =H6/L6-1 -> -0.16476553 | P6: =IF(D6<=MIN(H6,L6),"Food First",IF(H6<=L6,"Supermarket A","Supermarket B")) -> Food First
A7: Vegetables | B7: Pumpkin | C7: kg | D7: 2 | E7: Kg | F7: BBD/kg | G7: 3.52 | H7: 3.52 | I7: Kg | J7: BBD/kg | K7: 5.29 | L7: 5.29 | M7: =D7/H7-1 -> -0.43181818 | N7: =D7/L7-1 -> -0.62192817 | O7: =H7/L7-1 -> -0.33459357 | P7: =IF(D7<=MIN(H7,L7),"Food First",IF(H7<=L7,"Supermarket A","Supermarket B")) -> Food First
A8: Vegetables | B8: Red Cabbage | C8: kg | D8: 5 | E8: Kg | F8: BBD/kg | G8: 9.99 | H8: 9.99 | I8: Kg | J8: BBD/kg | K8: 9.99 | L8: 9.99 | M8: =D8/H8-1 -> -0.4994995 | N8: =D8/L8-1 -> -0.4994995 | O8: =H8/L8-1 -> 0 | P8: =IF(D8<=MIN(H8,L8),"Food First",IF(H8<=L8,"Supermarket A","Supermarket B")) -> Food First
A9: Vegetables | B9: Red Onions | C9: kg | D9: 6.7 | E9: Kg | F9: BBD/kg | G9: 11.88 | H9: 11.88 | I9: Kg | J9: BBD/kg | K9: 17.85 | L9: 17.85 | M9: =D9/H9-1 -> -0.43602694 | N9: =D9/L9-1 -> -0.62464986 | O9: =H9/L9-1 -> -0.33445378 | P9: =IF(D9<=MIN(H9,L9),"Food First",IF(H9<=L9,"Supermarket A","Supermarket B")) -> Food First
A10: Vegetables | B10: English Potatoes (Medium) | C10: kg | D10: 2 | E10: Kg | F10: BBD/kg | G10: 2.25 | H10: 2.25 | I10: Kg | J10: BBD/kg | K10: 2.59 | L10: 2.59 | M10: =D10/H10-1 -> -0.11111111 | N10: =D10/L10-1 -> -0.22779923 | O10: =H10/L10-1 -> -0.13127413 | P10: =IF(D10<=MIN(H10,L10),"Food First",IF(H10<=L10,"Supermarket A","Supermarket B")) -> Food First
A11: Vegetables | B11: Cucumbers | C11: kg | D11: 8.44 | E11: Kg | F11: BBD/kg | G11: 5.49 | H11: 5.49 | I11: Kg | J11: BBD/kg | K11: 5.29 | L11: 5.29 | M11: =D11/H11-1 -> 0.53734062 | N11: =D11/L11-1 -> 0.59546314 | O11: =H11/L11-1 -> 0.037807183 | P11: =IF(D11<=MIN(H11,L11),"Food First",IF(H11<=L11,"Supermarket A","Supermarket B")) -> Supermarket B
A12: Vegetables | B12: Zucchini | C12: kg | D12: 5 | E12: Kg | F12: BBD/kg | G12: 10.99 | H12: 10.99 | I12: Kg | J12: BBD/kg | K12: 14.69 | L12: 14.69 | M12: =D12/H12-1 -> -0.54504095 | N12: =D12/L12-1 -> -0.6596324 | O12: =H12/L12-1 -> -0.25187202 | P12: =IF(D12<=MIN(H12,L12),"Food First",IF(H12<=L12,"Supermarket A","Supermarket B")) -> Food First
A13: Vegetables | B13: Carrots | C13: kg | D13: 6.5 | E13: Kg | F13: BBD/kg | G13: 13.82 | H13: 13.82 | I13: 1 lb | J13: BBD/kg | K13: 3.89 | L13: 8.576 | M13: =D13/H13-1 -> -0.52966715 | N13: =D13/L13-1 -> -0.2420709 | O13: =H13/L13-1 -> 0.61147388 | P13: =IF(D13<=MIN(H13,L13),"Food First",IF(H13<=L13,"Supermarket A","Supermarket B")) -> Food First | Q13: 1 lb = 0.4536 kg: 3.89 / 0.4536 = 8.576 per kg.
A14: Fruits | B14: Tomatoes | C14: kg | D14: 14.3 | E14: Kg | F14: BBD/kg | G14: 15.99 | H14: 15.99 | I14: Kg | J14: BBD/kg | K14: 14.99 | L14: 14.99 | M14: =D14/H14-1 -> -0.10569106 | N14: =D14/L14-1 -> -0.046030687 | O14: =H14/L14-1 -> 0.066711141 | P14: =IF(D14<=MIN(H14,L14),"Food First",IF(H14<=L14,"Supermarket A","Supermarket B")) -> Food First
A15: Fruits | B15: Red Apples | C15: unit | D15: 1 | E15: unit | F15: BBD/unit | G15: 0.599 | H15: 0.599 | I15: unit | J15: BBD/unit | K15: 0.69 | L15: 0.69 | M15: =D15/H15-1 -> 0.66944908 | N15: =D15/L15-1 -> 0.44927536 | O15: =H15/L15-1 -> -0.13188406 | P15: =IF(D15<=MIN(H15,L15),"Food First",IF(H15<=L15,"Supermarket A","Supermarket B")) -> Supermarket A
A16: Fruits | B16: Green Apples | C16: unit | D16: 1.2 | E16: unit | F16: BBD/unit | G16: 1.99 | H16: 1.99 | I16: unit | J16: BBD/unit | K16: 1.49 | L16: 1.49 | M16: =D16/H16-1 -> -0.39698492 | N16: =D16/L16-1 -> -0.19463087 | O16: =H16/L16-1 -> 0.33557047 | P16: =IF(D16<=MIN(H16,L16),"Food First",IF(H16<=L16,"Supermarket A","Supermarket B")) -> Food First
A17: Fruits | B17: Oranges | C17: unit | D17: 1 | E17: unit | F17: BBD/unit | G17: 1.49 | H17: 1.49 | I17: unit | J17: BBD/unit | K17: 1.59 | L17: 1.59 | M17: =D17/H17-1 -> -0.32885906 | N17: =D17/L17-1 -> -0.37106918 | O17: =H17/L17-1 -> -0.062893082 | P17: =IF(D17<=MIN(H17,L17),"Food First",IF(H17<=L17,"Supermarket A","Supermarket B")) -> Food First
A18: Fruits | B18: Red Seedless Grapes | C18: kg | D18: 16.7 | E18: Kg | F18: BBD/kg | G18: 16.99 | H18: 16.99 | I18: Kg | J18: BBD/kg | K18: 18.99 | L18: 18.99 | M18: =D18/H18-1 -> -0.017068864 | N18: =D18/L18-1 -> -0.12058978 | O18: =H18/L18-1 -> -0.10531859 | P18: =IF(D18<=MIN(H18,L18),"Food First",IF(H18<=L18,"Supermarket A","Supermarket B")) -> Food First
A19: Fruits | B19: Green Seedless Grapes | C19: kg | D19: 16.7 | E19: Kg | F19: BBD/kg | G19: 16.88 | H19: 16.88 | I19: Kg | J19: BBD/kg | K19: 20.59 | L19: 20.59 | M19: =D19/H19-1 -> -0.010663507 | N19: =D19/L19-1 -> -0.18892666 | O19: =H19/L19-1 -> -0.18018456 | P19: =IF(D19<=MIN(H19,L19),"Food First",IF(H19<=L19,"Supermarket A","Supermarket B")) -> Food First
A20: Fruits | B20: Strawberries | C20: unit | D20: 12.88 | E20: 1 lb | F20: BBD/unit | G20: 12.99 | H20: 12.99 | I20: 1 lb | J20: BBD/unit | K20: 18.49 | L20: 18.49 | M20: =D20/H20-1 -> -0.0084680523 | N20: =D20/L20-1 -> -0.30340725 | O20: =H20/L20-1 -> -0.29745809 | P20: =IF(D20<=MIN(H20,L20),"Food First",IF(H20<=L20,"Supermarket A","Supermarket B")) -> Food First | Q20: Food First unit taken as the same 1 lb pack.
A21: Fruits | B21: Dragonfruit | C21: unit | D21: 10 | E21: unit | F21: BBD/unit | G21: 10.99 | H21: 10.99 | I21: unit | J21: BBD/unit | K21: 15.99 | L21: 15.99 | M21: =D21/H21-1 -> -0.090081893 | N21: =D21/L21-1 -> -0.37460913 | O21: =H21/L21-1 -> -0.31269543 | P21: =IF(D21<=MIN(H21,L21),"Food First",IF(H21<=L21,"Supermarket A","Supermarket B")) -> Food First
A22: Fruits | B22: Pears | C22: unit | D22: 0.9 | E22: unit | F22: BBD/unit | G22: 2.99 | H22: 2.99 | I22: unit | J22: BBD/unit | K22: 1.49 | L22: 1.49 | M22: =D22/H22-1 -> -0.69899666 | N22: =D22/L22-1 -> -0.39597315 | O22: =H22/L22-1 -> 1.0067114 | P22: =IF(D22<=MIN(H22,L22),"Food First",IF(H22<=L22,"Supermarket A","Supermarket B")) -> Food First
A23: Fruits | B23: Kiwis | C23: unit | D23: 1.99 | E23: unit | F23: BBD/unit | G23: 1.69 | H23: 1.69 | I23: unit | J23: BBD/unit | K23: 1.99 | L23: 1.99 | M23: =D23/H23-1 -> 0.17751479 | N23: =D23/L23-1 -> 0 | O23: =H23/L23-1 -> -0.15075377 | P23: =IF(D23<=MIN(H23,L23),"Food First",IF(H23<=L23,"Supermarket A","Supermarket B")) -> Supermarket A
A24: Fruits | B24: Jalapeno Peppers | C24: kg | D24: 15.5 | E24: Kg | F24: BBD/kg | G24: 28.2 | H24: 28.2 | I24: 340g | J24: BBD/kg | K24: 12.69 | L24: 37.3235 | M24: =D24/H24-1 -> -0.45035461 | N24: =D24/L24-1 -> -0.58471204 | O24: =H24/L24-1 -> -0.24444385 | P24: =IF(D24<=MIN(H24,L24),"Food First",IF(H24<=L24,"Supermarket A","Supermarket B")) -> Food First | Q24: 340 g = 0.34 kg: 12.69 / 0.34 = 37.32 per kg.
A25: Fruits | B25: Sweet Pepper Green | C25: kg | D25: 18.5 | E25: Kg | F25: BBD/kg | G25: 17.99 | H25: 17.99 | I25: Kg | J25: BBD/kg | K25: 19.99 | L25: 19.99 | M25: =D25/H25-1 -> 0.028349083 | N25: =D25/L25-1 -> -0.074537269 | O25: =H25/L25-1 -> -0.10005003 | P25: =IF(D25<=MIN(H25,L25),"Food First",IF(H25<=L25,"Supermarket A","Supermarket B")) -> Supermarket A | Q25: Supermarkets sell sweet peppers at one price regardless of colour.
A26: Fruits | B26: Sweet Pepper Red | C26: kg | D26: 19.5 | E26: Kg | F26: BBD/kg | G26: 17.99 | H26: 17.99 | I26: Kg | J26: BBD/kg | K26: 19.99 | L26: 19.99 | M26: =D26/H26-1 -> 0.08393552 | N26: =D26/L26-1 -> -0.024512256 | O26: =H26/L26-1 -> -0.10005003 | P26: =IF(D26<=MIN(H26,L26),"Food First",IF(H26<=L26,"Supermarket A","Supermarket B")) -> Supermarket A | Q26: Supermarkets sell sweet peppers at one price regardless of colour.
A27: Fruits | B27: Sweet Pepper Yellow | C27: kg | D27: 20.5 | E27: Kg | F27: BBD/kg | G27: 17.99 | H27: 17.99 | I27: Kg | J27: BBD/kg | K27: 19.99 | L27: 19.99 | M27: =D27/H27-1 -> 0.13952196 | N27: =D27/L27-1 -> 0.025512756 | O27: =H27/L27-1 -> -0.10005003 | P27: =IF(D27<=MIN(H27,L27),"Food First",IF(H27<=L27,"Supermarket A","Supermarket B")) -> Supermarket A | Q27: Supermarkets sell sweet peppers at one price regardless of colour.
A28: Fruits | B28: Grapefruit | C28: unit | D28: 3.3 | E28: unit | F28: BBD/unit | G28: 2.99 | H28: 2.99 | I28: unit | J28: BBD/unit | K28: 3.29 | L28: 3.29 | M28: =D28/H28-1 -> 0.10367893 | N28: =D28/L28-1 -> 0.0030395137 | O28: =H28/L28-1 -> -0.09118541 | P28: =IF(D28<=MIN(H28,L28),"Food First",IF(H28<=L28,"Supermarket A","Supermarket B")) -> Supermarket A
A29: Fruits | B29: Gala Apple | C29: unit | D29: 0.5 | E29: unit | F29: BBD/unit | G29: 1.99 | H29: 1.99 | I29: unit | J29: BBD/unit | K29: 1.45 | L29: 1.45 | M29: =D29/H29-1 -> -0.74874372 | N29: =D29/L29-1 -> -0.65517241 | O29: =H29/L29-1 -> 0.37241379 | P29: =IF(D29<=MIN(H29,L29),"Food First",IF(H29<=L29,"Supermarket A","Supermarket B")) -> Food First
A30: Fruits | B30: Mangoes | C30: kg | D30: 13.8 | E30: Kg | F30: BBD/kg | G30: 6.16 | H30: 6.16 | I30: Kg | J30: BBD/kg | K30: 7.36 | L30: 7.36 | M30: =D30/H30-1 -> 1.2402597 | N30: =D30/L30-1 -> 0.875 | O30: =H30/L30-1 -> -0.16304348 | P30: =IF(D30<=MIN(H30,L30),"Food First",IF(H30<=L30,"Supermarket A","Supermarket B")) -> Supermarket A
A31: Fruits | B31: Watermelon | C31: kg | D31: 4.5 | E31: Kg | F31: BBD/kg | G31: 6.99 | H31: 6.99 | I31: Kg | J31: BBD/kg | K31: 5.29 | L31: 5.29 | M31: =D31/H31-1 -> -0.35622318 | N31: =D31/L31-1 -> -0.14933837 | O31: =H31/L31-1 -> 0.32136106 | P31: =IF(D31<=MIN(H31,L31),"Food First",IF(H31<=L31,"Supermarket A","Supermarket B")) -> Food First
A32: Grocery | B32: Cooking Cream | C32: litre | D32: 15 | E32: litre | F32: BBD/litre | G32: 25.99 | H32: 25.99 | I32: litre | J32: BBD/litre | K32: 30.65 | L32: 30.65 | M32: =D32/H32-1 -> -0.42285494 | N32: =D32/L32-1 -> -0.51060359 | O32: =H32/L32-1 -> -0.15203915 | P32: =IF(D32<=MIN(H32,L32),"Food First",IF(H32<=L32,"Supermarket A","Supermarket B")) -> Food First
A33: Grocery | B33: Whipping Cream | C33: litre | D33: 15 | E33: litre | F33: BBD/litre | G33: 25.99 | H33: 25.99 | I33: litre | J33: BBD/litre | K33: 31.45 | L33: 31.45 | M33: =D33/H33-1 -> -0.42285494 | N33: =D33/L33-1 -> -0.52305246 | O33: =H33/L33-1 -> -0.1736089 | P33: =IF(D33<=MIN(H33,L33),"Food First",IF(H33<=L33,"Supermarket A","Supermarket B")) -> Food First
A34: Grocery | B34: Oat Milk | C34: litre | D34: 8.5 | E34: litre | F34: BBD/litre | G34: 8.45 | H34: 8.45 | I34: litre | J34: BBD/litre | K34: 10.99 | L34: 10.99 | M34: =D34/H34-1 -> 0.0059171598 | N34: =D34/L34-1 -> -0.22656961 | O34: =H34/L34-1 -> -0.2311192 | P34: =IF(D34<=MIN(H34,L34),"Food First",IF(H34<=L34,"Supermarket A","Supermarket B")) -> Supermarket A
A35: Grocery | B35: Whole Milk | C35: litre | D35: 5 | E35: litre | F35: BBD/litre | G35: 8.49 | H35: 8.49 | I35: litre | J35: BBD/litre | K35: 8.79 | L35: 8.79 | M35: =D35/H35-1 -> -0.41107185 | N35: =D35/L35-1 -> -0.43117179 | O35: =H35/L35-1 -> -0.034129693 | P35: =IF(D35<=MIN(H35,L35),"Food First",IF(H35<=L35,"Supermarket A","Supermarket B")) -> Food First
A36: Grocery | B36: Eggs | C36: dozen | D36: 9 | E36: dozen | F36: BBD/dozen | G36: 9.35 | H36: 9.35 | I36: dozen | J36: BBD/dozen | K36: 9.25 | L36: 9.25 | M36: =D36/H36-1 -> -0.037433155 | N36: =D36/L36-1 -> -0.027027027 | O36: =H36/L36-1 -> 0.010810811 | P36: =IF(D36<=MIN(H36,L36),"Food First",IF(H36<=L36,"Supermarket A","Supermarket B")) -> Food First
A37: Grocery | B37: Local Onions | C37: kg | D37: 2 | E37: Kg | F37: BBD/kg | G37: 3.52 | H37: 3.52 | I37: Kg | J37: BBD/kg | K37: 3.99 | L37: 3.99 | M37: =D37/H37-1 -> -0.43181818 | N37: =D37/L37-1 -> -0.49874687 | O37: =H37/L37-1 -> -0.11779449 | P37: =IF(D37<=MIN(H37,L37),"Food First",IF(H37<=L37,"Supermarket A","Supermarket B")) -> Food First
B39: Matched-basket total (sum of standardised prices) | D39: =SUM(D2:D37) -> 301.31 | H39: =SUM(H2:H37) -> 373.179 | L39: =SUM(L2:L37) -> 425.0295
A41: Legend
A42: Blue text = recorded price (editable input). Black = formula. % difference = first-named store / second-named store - 1; negative = first-named store cheaper.
...

Sheet Summary
A1: Metric | B1: Value
A2: Total items compared | B2: =COUNTA('Comparison Data'!$A$2:$A$37) -> 36
A3: Food First cheaper than Supermarket A | B3: =COUNTIF('Comparison Data'!$M$2:$M$37,"<0") -> 27
A4: Food First more expensive than Supermarket A | B4: =COUNTIF('Comparison Data'!$M$2:$M$37,">0") -> 9
A5: Food First cheaper than Supermarket B | B5: =COUNTIF('Comparison Data'!$N$2:$N$37,"<0") -> 30
A6: Food First more expensive than Supermarket B | B6: =COUNTIF('Comparison Data'!$N$2:$N$37,">0") -> 5
A7: Food First cheapest of all three stores | B7: =COUNTIF('Comparison Data'!$P$2:$P$37,"Food First") -> 27
A8: Mean % difference, Food First vs Supermarket A | B8: =AVERAGE('Comparison Data'!$M$2:$M$37) -> -0.16396557
A9: Median % difference, Food First vs Supermarket A | B9: =MEDIAN('Comparison Data'!$M$2:$M$37) -> -0.24412045
A10: Mean % difference, Food First vs Supermarket B | B10: =AVERAGE('Comparison Data'!$N$2:$N$37) -> -0.22688341
A11: Median % difference, Food First vs Supermarket B | B11: =MEDIAN('Comparison Data'!$N$2:$N$37) -> -0.23493506
A12: Mean % difference, Supermarket A vs Supermarket B | B12: =AVERAGE('Comparison Data'!$O$2:$O$37) -> -0.033199877
A13: Matched-basket total, Food First (BBD) | B13: =SUM('Comparison Data'!$D$2:$D$37) -> 301.31
A14: Matched-basket total, Supermarket A (BBD) | B14: =SUM('Comparison Data'!$H$2:$H$37) -> 373.179
A15: Matched-basket total, Supermarket B (BBD) | B15: =SUM('Comparison Data'!$L$2:$L$37) -> 425.0295
A16: Basket-total difference, Food First vs Supermarket A | B16: =B13/B14-1 -> -0.19258586
A17: Basket-total difference, Food First vs Supermarket B | B17: =B13/B15-1 -> -0.2910845
A19: Cheapest of the three stores | B19: Items
A20: Food First | B20: =COUNTIF('Comparison Data'!$P$2:$P$37,A20) -> 27
A21: Supermarket A | B21: =COUNTIF('Comparison Data'!$P$2:$P$37,A21) -> 8
A22: Supermarket B | B22: =COUNTIF('Comparison Data'!$P$2:$P$37,A22) -> 1
A24: Same price: Food First = Supermarket B | B24: =COUNTIF('Comparison Data'!$N$2:$N$37,0) -> 1
A25: Median % difference, Supermarket A vs Supermarket B | B25: =MEDIAN('Comparison Data'!$O$2:$O$37) -> -0.11155654
A26: Supermarket A cheaper than Supermarket B (items) | B26: =COUNTIF('Comparison Data'!$O$2:$O$37,"<0") -> 26
A27: Supermarket B cheaper than Supermarket A (items) | B27: =COUNTIF('Comparison Data'!$O$2:$O$37,">0") -> 9
A29: All values are formulas over the Comparison Data tab. Negative % = Food First (or the first-named store) cheaper.

Sheet Category Analysis
A1: Category | B1: Items listed | C1: Items matched | D1: Mean FF vs Supermarket A | E1: Median FF vs Supermarket A | F1: Mean FF vs Supermarket B | G1: Median FF vs Supermarket B | H1: Mean Supermarket A vs Supermarket B | I1: FF cheaper vs Supermarket A | J1: FF cheaper vs Supermarket B | K1: FF cheaper than both | L1: FF cheapest of three
A2: Vegetables | B2: =COUNTIF('Comparison Data'!$A$2:$A$37,$A2) -> 12 | C2: =COUNTIFS('Comparison Data'!$A$2:$A$37,$A2,'Comparison Data'!$M$2:$M$37,"<>") -> 12 | D2: =AVERAGEIFS('Comparison Data'!$M$2:$M$37,'Comparison Data'!$A$2:$A$37,$A2) -> -0.28443485 | E2: {=MEDIAN(IF('Comparison Data'!$A$2:$A$37=$A2,'Comparison Data'!$M$2:$M$37))} -> -0.40301798 | F2: =AVERAGEIFS('Comparison Data'!$N$2:$N$37,'Comparison Data'!$A$2:$A$37,$A2) -> -0.31832918 | G2: {=MEDIAN(IF('Comparison Data'!$A$2:$A$37=$A2,'Comparison Data'!$N$2:$N$37))} -> -0.3612689 | H2: =AVERAGEIFS('Comparison Data'!$O$2:$O$37,'Comparison Data'!$A$2:$A$37,$A2) -> -0.046672702 | I2: =COUNTIFS('Comparison Data'!$A$2:$A$37,$A2,'Comparison Data'!$M$2:$M$37,"<0") -> 11 | J2: =COUNTIFS('Comparison Data'!$A$2:$A$37,$A2,'Comparison Data'!$N$2:$N$37,"<0") -> 11 | K2: =SUMPRODUCT(('Comparison Data'!$A$2:$A$37=$A2)*('Comparison Data'!$M$2:$M$37<0)*('Comparison Data'!$N$2:$N$37<0)) -> 11 | L2: =COUNTIFS('Comparison Data'!$A$2:$A$37,$A2,'Comparison Data'!$P$2:$P$37,"Food First") -> 11
A3: Fruits | B3: =COUNTIF('Comparison Data'!$A$2:$A$37,$A3) -> 18 | C3: =COUNTIFS('Comparison Data'!$A$2:$A$37,$A3,'Comparison Data'!$M$2:$M$37,"<>") -> 18 | D3: =AVERAGEIFS('Comparison Data'!$M$2:$M$37,'Comparison Data'!$A$2:$A$37,$A3) -> -0.042745912 | E3: {=MEDIAN(IF('Comparison Data'!$A$2:$A$37=$A3,'Comparison Data'!$M$2:$M$37))} -> -0.013866186 | F3: =AVERAGEIFS('Comparison Data'!$N$2:$N$37,'Comparison Data'!$A$2:$A$37,$A3) -> -0.11837119 | G3: {=MEDIAN(IF('Comparison Data'!$A$2:$A$37=$A3,'Comparison Data'!$N$2:$N$37))} -> -0.13496408 | H3: =AVERAGEIFS('Comparison Data'!$O$2:$O$37,'Comparison Data'!$A$2:$A$37,$A3) -> 0.003486527 | I3: =COUNTIFS('Comparison Data'!$A$2:$A$37,$A3,'Comparison Data'!$M$2:$M$37,"<0") -> 11 | J3: =COUNTIFS('Comparison Data'!$A$2:$A$37,$A3,'Comparison Data'!$N$2:$N$37,"<0") -> 13 | K3: =SUMPRODUCT(('Comparison Data'!$A$2:$A$37=$A3)*('Comparison Data'!$M$2:$M$37<0)*('Comparison Data'!$N$2:$N$37<0)) -> 11 | L3: =COUNTIFS('Comparison Data'!$A$2:$A$37,$A3,'Comparison Data'!$P$2:$P$37,"Food First") -> 11
A4: Grocery | B4: =COUNTIF('Comparison Data'!$A$2:$A$37,$A4) -> 6 | C4: =COUNTIFS('Comparison Data'!$A$2:$A$37,$A4,'Comparison Data'!$M$2:$M$37,"<>") -> 6 | D4: =AVERAGEIFS('Comparison Data'!$M$2:$M$37,'Comparison Data'!$A$2:$A$37,$A4) -> -0.28668599 | E4: {=MEDIAN(IF('Comparison Data'!$A$2:$A$37=$A4,'Comparison Data'!$M$2:$M$37))} -> -0.4169634 | F4: =AVERAGEIFS('Comparison Data'!$N$2:$N$37,'Comparison Data'!$A$2:$A$37,$A4) -> -0.36952856 | G4: {=MEDIAN(IF('Comparison Data'!$A$2:$A$37=$A4,'Comparison Data'!$N$2:$N$37))} -> -0.46495933 | H4: =AVERAGEIFS('Comparison Data'!$O$2:$O$37,'Comparison Data'!$A$2:$A$37,$A4) -> -0.11631344 | I4: =COUNTIFS('Comparison Data'!$A$2:$A$37,$A4,'Comparison Data'!$M$2:$M$37,"<0") -> 5 | J4: =COUNTIFS('Comparison Data'!$A$2:$A$37,$A4,'Comparison Data'!$N$2:$N$37,"<0") -> 6 | K4: =SUMPRODUCT(('Comparison Data'!$A$2:$A$37=$A4)*('Comparison Data'!$M$2:$M$37<0)*('Comparison Data'!$N$2:$N$37<0)) -> 5 | L4: =COUNTIFS('Comparison Data'!$A$2:$A$37,$A4,'Comparison Data'!$P$2:$P$37,"Food First") -> 5
A5: All | B5: =COUNTA('Comparison Data'!$A$2:$A$37) -> 36 | C5: =COUNT('Comparison Data'!$M$2:$M$37) -> 36 | D5: =AVERAGE('Comparison Data'!$M$2:$M$37) -> -0.16396557 | E5: =MEDIAN('Comparison Data'!$M$2:$M$37) -> -0.24412045 | F5: =AVERAGE('Comparison Data'!$N$2:$N$37) -> -0.22688341 | G5: =MEDIAN('Comparison Data'!$N$2:$N$37) -> -0.23493506 | H5: =AVERAGE('Comparison Data'!$O$2:$O$37) -> -0.033199877 | I5: =COUNTIF('Comparison Data'!$M$2:$M$37,"<0") -> 27 | J5: =COUNTIF('Comparison Data'!$N$2:$N$37,"<0") -> 30 | K5: =SUMPRODUCT(('Comparison Data'!$M$2:$M$37<0)*('Comparison Data'!$N$2:$N$37<0)) -> 27 | L5: =COUNTIF('Comparison Data'!$P$2:$P$37,"Food First") -> 27
A7: Items listed = rows in Comparison Data; items matched = rows with a computed % difference (all rows, since excluded products are not in this workbook).
A8: Category medians use an array formula MEDIAN(IF(...)). Negative % = Food First (or first-named store) cheaper.
A10: Chart data (feeds the Charts tab)
A11: Category | B11: Item | C11: FF vs Supermarket A | D11: FF vs Supermarket B
A12: ='Comparison Data'!A2 -> Vegetables | B12: ='Comparison Data'!B2 -> Broccoli | C12: ='Comparison Data'!M2 -> -0.066044029 | D12: ='Comparison Data'!N2 -> -0.12445278
A13: ='Comparison Data'!A3 -> Vegetables | B13: ='Comparison Data'!B3 -> Cauliflower | C13: ='Comparison Data'!M3 -> -0.239493 | D13: ='Comparison Data'!N3 -> -0.36631462
A14: ='Comparison Data'!A4 -> Vegetables | B14: ='Comparison Data'!B4 -> Romaine Lettuce | C14: ='Comparison Data'!M4 -> -0.37421777 | D14: ='Comparison Data'!N4 -> -0.13644214
A15: ='Comparison Data'!A5 -> Vegetables | B15: ='Comparison Data'!B5 -> Iceberg Lettuce | C15: ='Comparison Data'!M5 -> -0.24874791 | D15: ='Comparison Data'!N5 -> -0.35622318
A16: ='Comparison Data'!A6 -> Vegetables | B16: ='Comparison Data'!B6 -> Local Cabbage | C16: ='Comparison Data'!M6 -> -0.46889226 | D16: ='Comparison Data'!N6 -> -0.55640051
A17: ='Comparison Data'!A7 -> Vegetables | B17: ='Comparison Data'!B7 -> Pumpkin | C17: ='Comparison Data'!M7 -> -0.43181818 | D17: ='Comparison Data'!N7 -> -0.62192817
A18: ='Comparison Data'!A8 -> Vegetables | B18: ='Comparison Data'!B8 -> Red Cabbage | C18: ='Comparison Data'!M8 -> -0.4994995 | D18: ='Comparison Data'!N8 -> -0.4994995
A19: ='Comparison Data'!A9 -> Vegetables | B19: ='Comparison Data'!B9 -> Red Onions | C19: ='Comparison Data'!M9 -> -0.43602694 | D19: ='Comparison Data'!N9 -> -0.62464986
A20: ='Comparison Data'!A10 -> Vegetables | B20: ='Comparison Data'!B10 -> English Potatoes (Medium) | C20: ='Comparison Data'!M10 -> -0.11111111 | D20: ='Comparison Data'!N10 -> -0.22779923
A21: ='Comparison Data'!A11 -> Vegetables | B21: ='Comparison Data'!B11 -> Cucumbers | C21: ='Comparison Data'!M11 -> 0.53734062 | D21: ='Comparison Data'!N11 -> 0.59546314
A22: ='Comparison Data'!A12 -> Vegetables | B22: ='Comparison Data'!B12 -> Zucchini | C22: ='Comparison Data'!M12 -> -0.54504095 | D22: ='Comparison Data'!N12 -> -0.6596324
A23: ='Comparison Data'!A13 -> Vegetables | B23: ='Comparison Data'!B13 -> Carrots | C23: ='Comparison Data'!M13 -> -0.52966715 | D23: ='Comparison Data'!N13 -> -0.2420709
... A47: ='Comparison Data'!A37 -> Grocery | B47: ='Comparison Data'!B37 -> Local Onions | C47: ='Comparison Data'!M37 -> -0.43181818 | D47: ='Comparison Data'!N37 -> -0.49874687

Sheet Charts
A1: CHARTS
A2: Bars below zero = Food First cheaper; above zero = Food First more expensive. Charts read live from the other tabs.
